<mujoco model="jetarm gripper">
    <compiler angle="radian" autolimits="true"/>
    <option integrator="implicitfast" gravity="0 0 0"/>
    <default>
        <default class="jetarm_gripper">
            <joint armature="0.1" damping="10" frictionloss="0.1"/>
            <!-- <general dyntype="none" biastype="affine" gainprm="5" biasprm="0 -5 -1" ctrlrange="-1.57 1.57" forcerange="-20 20"/> -->
            <general dyntype="none" biastype="affine" ctrlrange="0 1.57" forcerange="-20 20"/>
            <geom rgba="0.1 0.1 0.1 1" type="mesh" contype="0" conaffinity="0" group="1"/>
            <default class="visual">
                <geom type="mesh" contype="0" conaffinity="0" group="2"/>
            </default>
            <default class="collision">
                <geom type="mesh" contype="1" conaffinity="1" condim="4" group="3" friction="1 1 1" solimp="1 1 1" solref="0.01 1"/>
            </default>
        </default>
    </default>
    <!-- Visual meshes -->
    <asset>
        <mesh name="Gripper_Base" file="meshes/Gripper_Base.STL" scale="0.001 0.001 0.001"/>
        <mesh name="r_link" file="meshes/r_link.stl"/>
        <mesh name="l_link" file="meshes/l_link.stl"/>
        <mesh name="r_in_link" file="meshes/r_in_link.stl"/>
        <mesh name="r_out_link" file="meshes/r_out_link.stl"/>
        <mesh name="l_in_link" file="meshes/l_in_link.stl"/>
        <mesh name="l_out_link" file="meshes/l_out_link.stl"/>
    </asset>
    <worldbody>
        <body name="gripper" childclass="jetarm_gripper">
            <geom type="mesh" contype="0" conaffinity="0" density="0" mass="0.0174988102544488" rgba="0.15 0.15 0.15 1" mesh="Gripper_Base" class="visual"/>
            <!-- collision -->
            <geom type="mesh" contype="1" conaffinity="1" rgba="0.8 0.8 0.8 1" mesh="Gripper_Base" class="collision"/>
            <!-- This site was added for visualization. -->
            <!-- <body name="eef" pos="0 0 0" quat="0 1 1 0"> -->
            <body name="eef" pos="0 0 0.075" euler="0 3.1415926 1.5707963">
                <site name="grip_site" pos="0 0 0" size="0.005" rgba="1 0 0 0.1" type="sphere" group="1"/>
                <site name="ee_x" pos="0.2 0 0" size="0.005 .2"  quat="0.707105  0 0.707108 0 " rgba="1 0 0 0.1" type="cylinder" group="1"/>
                <site name="ee_y" pos="0 0.2 0" size="0.005 .2" quat="0.707105 0.707108 0 0" rgba="0 1 0 0.1" type="cylinder" group="1"/>
                <site name="ee_z" pos="0 0 0.2" size="0.005 .2" quat="1 0 0 0" rgba="0 0 1 0.5" type="cylinder" group="1"/>
                <site name="ee_x_ne" pos="-0.2 0 0" size="0.005 .2"  quat="0.707105  0 0.707108 0 " rgba="1 1 1 0.1" type="cylinder" group="1"/>
                <site name="ee_y_ne" pos="0 -0.2 0" size="0.005 .2" quat="0.707105 0.707108 0 0" rgba="1 1 1 0.1" type="cylinder" group="1"/>
                <site name="ee_z_ne" pos="0 0 -0.2" size="0.005 .2" quat="1 0 0 0" rgba="1 1 1 0.1" type="cylinder" group="1"/>
            </body>
            <body name="r_link" pos="-0.00704769 -0.0139998 0.0270071" quat="0.707107 0 0 0.707107">
                <inertial pos="0.000541258 -0.0015 0.00625151" mass="1e-05" diaginertia="10 10 10"/>
                <joint name="r_joint" pos="0 0 0" axis="0 -1 0" range="0 1.57" actuatorfrcrange="-1000 1000"/>
                <geom type="mesh" contype="0" conaffinity="0" density="0" rgba="0.3 0.3 0.3 1" mesh="r_link" class="visual"/>
                <!-- collision -->
                <!-- <geom type="mesh" contype="1" conaffinity="1" rgba="0.8 0.8 0.8 1" mesh="r_link" class="collision"/>  -->
            </body>
            <body name="l_link" pos="-0.00703115 0.0140002 0.027008" quat="0.707107 0 0 0.707107">
                <inertial pos="0.0054115 -0.0015023 0.0058059" mass="1e-05" diaginertia="10 10 10"/>
                <!-- <joint name="l_joint" pos="0 0 0" axis="0 1 0" range="-1.57 1.57" actuatorfrcrange="-1000 1000"/> -->
                <joint name="l_joint" pos="0 0 0" axis="0 1 0" range="0 1.57" actuatorfrcrange="-1000 1000"/>
                <geom type="mesh" contype="0" conaffinity="0" density="0" rgba="0.3 0.3 0.3 1" mesh="l_link" class="visual"/>
                <!-- collision -->
                <!-- <geom type="mesh" contype="1" conaffinity="1" rgba="0.8 0.8 0.8 1" mesh="l_link" class="collision"/>  -->
            </body>
            <body name="r_in_link" pos="-0.0065253 -0.0075039 0.0459914" quat="0.707107 0 0 0.707107">
                <inertial pos="-1.7319e-09 -0.006 0.0145" mass="1e-05" diaginertia="10 10 10"/>
                <joint name="r_in_joint" pos="0 0 0" axis="0 1 0" range="-1.57 0" actuatorfrcrange="-1000 1000"/>
                <geom type="mesh" contype="0" conaffinity="0" density="0" rgba="0.3 0.3 0.3 1" mesh="r_in_link" class="visual"/>
                <!-- collision -->
                <!-- <geom type="mesh" contype="1" conaffinity="1" rgba="0.8 0.8 0.8 1" mesh="r_in_link" class="collision"/>  -->
                <body name="r_out_link" pos="0 0 0.029">
                    <inertial pos="-0.0013784 -0.0060519 0.0096418" mass="1e-05" diaginertia="10 10 10"/>
                    <joint name="r_out_joint" pos="0 0 0" axis="0 1 0" range="0 1.57" actuatorfrcrange="-1000 1000"/>
                    <geom type="mesh" contype="0" conaffinity="0" density="0" rgba="0.3 0.3 0.3 1" mesh="r_out_link" class="visual"/>
                    <!-- collision -->
                    <geom type="mesh" contype="1" conaffinity="1" rgba="0.8 0.8 0.8 1" mesh="r_out_link" class="collision"/>
                </body>
            </body>
            <body name="l_in_link" pos="-0.0065053 0.0075039 0.0459911" quat="0.707107 0 0 0.707107">
                <inertial pos="-1.7319e-09 -0.006 0.0145" mass="1e-05" diaginertia="10 10 10"/>
                <joint name="l_in_joint" pos="0 0 0" axis="0 -1 0" range="-1.57 0" actuatorfrcrange="-1000 1000"/>
                <geom type="mesh" contype="0" conaffinity="0" density="0" rgba="0.3 0.3 0.3 1" mesh="l_in_link" class="visual"/>
                <!-- collision -->
                <!-- <geom type="mesh" contype="1" conaffinity="1" rgba="0.8 0.8 0.8 1" mesh="l_in_link" class="collision"/> -->
                <body name="l_out_link" pos="0 0 0.029">
                    <inertial pos="0.0013784 -0.0060519 0.0096418" mass="1e-05" diaginertia="10 10 10"/>
                    <joint name="l_out_joint" pos="0 0 0" axis="0 -1 0" range="0 1.57" actuatorfrcrange="-1000 1000"/>
                    <geom type="mesh" contype="0" conaffinity="0" density="0" rgba="0.3 0.3 0.3 1" mesh="l_out_link" class="visual"/>
                    <!-- collision -->
                    <geom type="mesh" contype="1" conaffinity="1" rgba="0.8 0.8 0.8 1" mesh="l_out_link" class="collision"/>
                </body>
            </body>
        </body>
    </worldbody>
    <contact>
        <exclude body1='r_in_link' body2='r_out_link'/>
        <exclude body1='l_in_link' body2='l_out_link'/>
    </contact>
    <equality>
        <connect anchor="0 0 0.029" body1="r_link" body2="r_out_link"/>
        <connect anchor="0 0 0.029" body1="l_link" body2="l_out_link"/>
        <joint joint1="r_joint" joint2="l_joint"/>
    </equality>
    <equality>
        <joint joint1="r_joint" joint2="l_joint"/>
    </equality>
    <actuator>
        <general class="jetarm_gripper" name="actuator6" joint="r_joint" forcerange="-100 100" ctrlrange="-1.5 1.5" gainprm="100 0 0" biasprm="0 -50 -1"/>
        <!-- <general class="jetarm_gripper" name="actuator1" joint="r_joint" ctrlrange="-1.57 1.57"/> -->
        <!-- <position name="actuator6" joint="r_joint" kp="50" ctrlrange="0 1.57" ctrllimited="true"/> -->
    </actuator>
    
    <!-- <keyframe> -->
        <!-- <key qpos="1.51 1.51 -1.57 1.19 -1.57 1.19" ctrl="1.57"/> -->
        <!-- <key name="gripper_home" ctrl="1.57"/> -->
    <!-- </keyframe> -->
</mujoco>